{
 "cells": [
  {
   "cell_type": "code",
   "execution_count": 2,
   "metadata": {},
   "outputs": [
    {
     "name": "stdout",
     "output_type": "stream",
     "text": [
      "Requirement already satisfied: sqlalchemy in c:\\users\\aloag\\appdata\\local\\packages\\pythonsoftwarefoundation.python.3.10_qbz5n2kfra8p0\\localcache\\local-packages\\python310\\site-packages (1.4.44)\n",
      "Collecting psycopg2-binary\n",
      "  Downloading psycopg2_binary-2.9.5-cp310-cp310-win_amd64.whl (1.2 MB)\n",
      "     ---------------------------------------- 1.2/1.2 MB 18.4 MB/s eta 0:00:00\n",
      "Requirement already satisfied: greenlet!=0.4.17 in c:\\users\\aloag\\appdata\\local\\packages\\pythonsoftwarefoundation.python.3.10_qbz5n2kfra8p0\\localcache\\local-packages\\python310\\site-packages (from sqlalchemy) (2.0.1)\n",
      "Installing collected packages: psycopg2-binary\n",
      "Successfully installed psycopg2-binary-2.9.5\n"
     ]
    }
   ],
   "source": [
    "!pip install sqlalchemy psycopg2-binary"
   ]
  },
  {
   "cell_type": "code",
   "execution_count": 3,
   "metadata": {},
   "outputs": [],
   "source": [
    "from sqlalchemy import create_engine"
   ]
  },
  {
   "cell_type": "code",
   "execution_count": 8,
   "metadata": {},
   "outputs": [],
   "source": [
    "engine = create_engine('postgresql://root:root@localhost:5432/ny_taxi')"
   ]
  },
  {
   "cell_type": "code",
   "execution_count": 9,
   "metadata": {},
   "outputs": [
    {
     "ename": "OperationalError",
     "evalue": "(psycopg2.OperationalError) connection to server at \"localhost\" (::1), port 5432 failed: FATAL:  password authentication failed for user \"root\"\n\n(Background on this error at: https://sqlalche.me/e/14/e3q8)",
     "output_type": "error",
     "traceback": [
      "\u001b[1;31m---------------------------------------------------------------------------\u001b[0m",
      "\u001b[1;31mOperationalError\u001b[0m                          Traceback (most recent call last)",
      "File \u001b[1;32m~\\AppData\\Local\\Packages\\PythonSoftwareFoundation.Python.3.10_qbz5n2kfra8p0\\LocalCache\\local-packages\\Python310\\site-packages\\sqlalchemy\\engine\\base.py:3361\u001b[0m, in \u001b[0;36mEngine._wrap_pool_connect\u001b[1;34m(self, fn, connection)\u001b[0m\n\u001b[0;32m   3360\u001b[0m \u001b[39mtry\u001b[39;00m:\n\u001b[1;32m-> 3361\u001b[0m     \u001b[39mreturn\u001b[39;00m fn()\n\u001b[0;32m   3362\u001b[0m \u001b[39mexcept\u001b[39;00m dialect\u001b[39m.\u001b[39mdbapi\u001b[39m.\u001b[39mError \u001b[39mas\u001b[39;00m e:\n",
      "File \u001b[1;32m~\\AppData\\Local\\Packages\\PythonSoftwareFoundation.Python.3.10_qbz5n2kfra8p0\\LocalCache\\local-packages\\Python310\\site-packages\\sqlalchemy\\pool\\base.py:325\u001b[0m, in \u001b[0;36mPool.connect\u001b[1;34m(self)\u001b[0m\n\u001b[0;32m    318\u001b[0m \u001b[39m\"\"\"Return a DBAPI connection from the pool.\u001b[39;00m\n\u001b[0;32m    319\u001b[0m \n\u001b[0;32m    320\u001b[0m \u001b[39mThe connection is instrumented such that when its\u001b[39;00m\n\u001b[1;32m   (...)\u001b[0m\n\u001b[0;32m    323\u001b[0m \n\u001b[0;32m    324\u001b[0m \u001b[39m\"\"\"\u001b[39;00m\n\u001b[1;32m--> 325\u001b[0m \u001b[39mreturn\u001b[39;00m _ConnectionFairy\u001b[39m.\u001b[39;49m_checkout(\u001b[39mself\u001b[39;49m)\n",
      "File \u001b[1;32m~\\AppData\\Local\\Packages\\PythonSoftwareFoundation.Python.3.10_qbz5n2kfra8p0\\LocalCache\\local-packages\\Python310\\site-packages\\sqlalchemy\\pool\\base.py:888\u001b[0m, in \u001b[0;36m_ConnectionFairy._checkout\u001b[1;34m(cls, pool, threadconns, fairy)\u001b[0m\n\u001b[0;32m    887\u001b[0m \u001b[39mif\u001b[39;00m \u001b[39mnot\u001b[39;00m fairy:\n\u001b[1;32m--> 888\u001b[0m     fairy \u001b[39m=\u001b[39m _ConnectionRecord\u001b[39m.\u001b[39;49mcheckout(pool)\n\u001b[0;32m    890\u001b[0m     fairy\u001b[39m.\u001b[39m_pool \u001b[39m=\u001b[39m pool\n",
      "File \u001b[1;32m~\\AppData\\Local\\Packages\\PythonSoftwareFoundation.Python.3.10_qbz5n2kfra8p0\\LocalCache\\local-packages\\Python310\\site-packages\\sqlalchemy\\pool\\base.py:491\u001b[0m, in \u001b[0;36m_ConnectionRecord.checkout\u001b[1;34m(cls, pool)\u001b[0m\n\u001b[0;32m    489\u001b[0m \u001b[39m@classmethod\u001b[39m\n\u001b[0;32m    490\u001b[0m \u001b[39mdef\u001b[39;00m \u001b[39mcheckout\u001b[39m(\u001b[39mcls\u001b[39m, pool):\n\u001b[1;32m--> 491\u001b[0m     rec \u001b[39m=\u001b[39m pool\u001b[39m.\u001b[39;49m_do_get()\n\u001b[0;32m    492\u001b[0m     \u001b[39mtry\u001b[39;00m:\n",
      "File \u001b[1;32m~\\AppData\\Local\\Packages\\PythonSoftwareFoundation.Python.3.10_qbz5n2kfra8p0\\LocalCache\\local-packages\\Python310\\site-packages\\sqlalchemy\\pool\\impl.py:145\u001b[0m, in \u001b[0;36mQueuePool._do_get\u001b[1;34m(self)\u001b[0m\n\u001b[0;32m    144\u001b[0m \u001b[39mexcept\u001b[39;00m:\n\u001b[1;32m--> 145\u001b[0m     \u001b[39mwith\u001b[39;00m util\u001b[39m.\u001b[39msafe_reraise():\n\u001b[0;32m    146\u001b[0m         \u001b[39mself\u001b[39m\u001b[39m.\u001b[39m_dec_overflow()\n",
      "File \u001b[1;32m~\\AppData\\Local\\Packages\\PythonSoftwareFoundation.Python.3.10_qbz5n2kfra8p0\\LocalCache\\local-packages\\Python310\\site-packages\\sqlalchemy\\util\\langhelpers.py:70\u001b[0m, in \u001b[0;36msafe_reraise.__exit__\u001b[1;34m(self, type_, value, traceback)\u001b[0m\n\u001b[0;32m     69\u001b[0m     \u001b[39mif\u001b[39;00m \u001b[39mnot\u001b[39;00m \u001b[39mself\u001b[39m\u001b[39m.\u001b[39mwarn_only:\n\u001b[1;32m---> 70\u001b[0m         compat\u001b[39m.\u001b[39;49mraise_(\n\u001b[0;32m     71\u001b[0m             exc_value,\n\u001b[0;32m     72\u001b[0m             with_traceback\u001b[39m=\u001b[39;49mexc_tb,\n\u001b[0;32m     73\u001b[0m         )\n\u001b[0;32m     74\u001b[0m \u001b[39melse\u001b[39;00m:\n",
      "File \u001b[1;32m~\\AppData\\Local\\Packages\\PythonSoftwareFoundation.Python.3.10_qbz5n2kfra8p0\\LocalCache\\local-packages\\Python310\\site-packages\\sqlalchemy\\util\\compat.py:210\u001b[0m, in \u001b[0;36mraise_\u001b[1;34m(***failed resolving arguments***)\u001b[0m\n\u001b[0;32m    209\u001b[0m \u001b[39mtry\u001b[39;00m:\n\u001b[1;32m--> 210\u001b[0m     \u001b[39mraise\u001b[39;00m exception\n\u001b[0;32m    211\u001b[0m \u001b[39mfinally\u001b[39;00m:\n\u001b[0;32m    212\u001b[0m     \u001b[39m# credit to\u001b[39;00m\n\u001b[0;32m    213\u001b[0m     \u001b[39m# https://cosmicpercolator.com/2016/01/13/exception-leaks-in-python-2-and-3/\u001b[39;00m\n\u001b[0;32m    214\u001b[0m     \u001b[39m# as the __traceback__ object creates a cycle\u001b[39;00m\n",
      "File \u001b[1;32m~\\AppData\\Local\\Packages\\PythonSoftwareFoundation.Python.3.10_qbz5n2kfra8p0\\LocalCache\\local-packages\\Python310\\site-packages\\sqlalchemy\\pool\\impl.py:143\u001b[0m, in \u001b[0;36mQueuePool._do_get\u001b[1;34m(self)\u001b[0m\n\u001b[0;32m    142\u001b[0m \u001b[39mtry\u001b[39;00m:\n\u001b[1;32m--> 143\u001b[0m     \u001b[39mreturn\u001b[39;00m \u001b[39mself\u001b[39;49m\u001b[39m.\u001b[39;49m_create_connection()\n\u001b[0;32m    144\u001b[0m \u001b[39mexcept\u001b[39;00m:\n",
      "File \u001b[1;32m~\\AppData\\Local\\Packages\\PythonSoftwareFoundation.Python.3.10_qbz5n2kfra8p0\\LocalCache\\local-packages\\Python310\\site-packages\\sqlalchemy\\pool\\base.py:271\u001b[0m, in \u001b[0;36mPool._create_connection\u001b[1;34m(self)\u001b[0m\n\u001b[0;32m    269\u001b[0m \u001b[39m\"\"\"Called by subclasses to create a new ConnectionRecord.\"\"\"\u001b[39;00m\n\u001b[1;32m--> 271\u001b[0m \u001b[39mreturn\u001b[39;00m _ConnectionRecord(\u001b[39mself\u001b[39;49m)\n",
      "File \u001b[1;32m~\\AppData\\Local\\Packages\\PythonSoftwareFoundation.Python.3.10_qbz5n2kfra8p0\\LocalCache\\local-packages\\Python310\\site-packages\\sqlalchemy\\pool\\base.py:386\u001b[0m, in \u001b[0;36m_ConnectionRecord.__init__\u001b[1;34m(self, pool, connect)\u001b[0m\n\u001b[0;32m    385\u001b[0m \u001b[39mif\u001b[39;00m connect:\n\u001b[1;32m--> 386\u001b[0m     \u001b[39mself\u001b[39;49m\u001b[39m.\u001b[39;49m__connect()\n\u001b[0;32m    387\u001b[0m \u001b[39mself\u001b[39m\u001b[39m.\u001b[39mfinalize_callback \u001b[39m=\u001b[39m deque()\n",
      "File \u001b[1;32m~\\AppData\\Local\\Packages\\PythonSoftwareFoundation.Python.3.10_qbz5n2kfra8p0\\LocalCache\\local-packages\\Python310\\site-packages\\sqlalchemy\\pool\\base.py:684\u001b[0m, in \u001b[0;36m_ConnectionRecord.__connect\u001b[1;34m(self)\u001b[0m\n\u001b[0;32m    683\u001b[0m \u001b[39mexcept\u001b[39;00m \u001b[39mException\u001b[39;00m \u001b[39mas\u001b[39;00m e:\n\u001b[1;32m--> 684\u001b[0m     \u001b[39mwith\u001b[39;00m util\u001b[39m.\u001b[39msafe_reraise():\n\u001b[0;32m    685\u001b[0m         pool\u001b[39m.\u001b[39mlogger\u001b[39m.\u001b[39mdebug(\u001b[39m\"\u001b[39m\u001b[39mError on connect(): \u001b[39m\u001b[39m%s\u001b[39;00m\u001b[39m\"\u001b[39m, e)\n",
      "File \u001b[1;32m~\\AppData\\Local\\Packages\\PythonSoftwareFoundation.Python.3.10_qbz5n2kfra8p0\\LocalCache\\local-packages\\Python310\\site-packages\\sqlalchemy\\util\\langhelpers.py:70\u001b[0m, in \u001b[0;36msafe_reraise.__exit__\u001b[1;34m(self, type_, value, traceback)\u001b[0m\n\u001b[0;32m     69\u001b[0m     \u001b[39mif\u001b[39;00m \u001b[39mnot\u001b[39;00m \u001b[39mself\u001b[39m\u001b[39m.\u001b[39mwarn_only:\n\u001b[1;32m---> 70\u001b[0m         compat\u001b[39m.\u001b[39;49mraise_(\n\u001b[0;32m     71\u001b[0m             exc_value,\n\u001b[0;32m     72\u001b[0m             with_traceback\u001b[39m=\u001b[39;49mexc_tb,\n\u001b[0;32m     73\u001b[0m         )\n\u001b[0;32m     74\u001b[0m \u001b[39melse\u001b[39;00m:\n",
      "File \u001b[1;32m~\\AppData\\Local\\Packages\\PythonSoftwareFoundation.Python.3.10_qbz5n2kfra8p0\\LocalCache\\local-packages\\Python310\\site-packages\\sqlalchemy\\util\\compat.py:210\u001b[0m, in \u001b[0;36mraise_\u001b[1;34m(***failed resolving arguments***)\u001b[0m\n\u001b[0;32m    209\u001b[0m \u001b[39mtry\u001b[39;00m:\n\u001b[1;32m--> 210\u001b[0m     \u001b[39mraise\u001b[39;00m exception\n\u001b[0;32m    211\u001b[0m \u001b[39mfinally\u001b[39;00m:\n\u001b[0;32m    212\u001b[0m     \u001b[39m# credit to\u001b[39;00m\n\u001b[0;32m    213\u001b[0m     \u001b[39m# https://cosmicpercolator.com/2016/01/13/exception-leaks-in-python-2-and-3/\u001b[39;00m\n\u001b[0;32m    214\u001b[0m     \u001b[39m# as the __traceback__ object creates a cycle\u001b[39;00m\n",
      "File \u001b[1;32m~\\AppData\\Local\\Packages\\PythonSoftwareFoundation.Python.3.10_qbz5n2kfra8p0\\LocalCache\\local-packages\\Python310\\site-packages\\sqlalchemy\\pool\\base.py:680\u001b[0m, in \u001b[0;36m_ConnectionRecord.__connect\u001b[1;34m(self)\u001b[0m\n\u001b[0;32m    679\u001b[0m \u001b[39mself\u001b[39m\u001b[39m.\u001b[39mstarttime \u001b[39m=\u001b[39m time\u001b[39m.\u001b[39mtime()\n\u001b[1;32m--> 680\u001b[0m \u001b[39mself\u001b[39m\u001b[39m.\u001b[39mdbapi_connection \u001b[39m=\u001b[39m connection \u001b[39m=\u001b[39m pool\u001b[39m.\u001b[39;49m_invoke_creator(\u001b[39mself\u001b[39;49m)\n\u001b[0;32m    681\u001b[0m pool\u001b[39m.\u001b[39mlogger\u001b[39m.\u001b[39mdebug(\u001b[39m\"\u001b[39m\u001b[39mCreated new connection \u001b[39m\u001b[39m%r\u001b[39;00m\u001b[39m\"\u001b[39m, connection)\n",
      "File \u001b[1;32m~\\AppData\\Local\\Packages\\PythonSoftwareFoundation.Python.3.10_qbz5n2kfra8p0\\LocalCache\\local-packages\\Python310\\site-packages\\sqlalchemy\\engine\\create.py:578\u001b[0m, in \u001b[0;36mcreate_engine.<locals>.connect\u001b[1;34m(connection_record)\u001b[0m\n\u001b[0;32m    577\u001b[0m             \u001b[39mreturn\u001b[39;00m connection\n\u001b[1;32m--> 578\u001b[0m \u001b[39mreturn\u001b[39;00m dialect\u001b[39m.\u001b[39mconnect(\u001b[39m*\u001b[39mcargs, \u001b[39m*\u001b[39m\u001b[39m*\u001b[39mcparams)\n",
      "File \u001b[1;32m~\\AppData\\Local\\Packages\\PythonSoftwareFoundation.Python.3.10_qbz5n2kfra8p0\\LocalCache\\local-packages\\Python310\\site-packages\\sqlalchemy\\engine\\default.py:598\u001b[0m, in \u001b[0;36mDefaultDialect.connect\u001b[1;34m(self, *cargs, **cparams)\u001b[0m\n\u001b[0;32m    596\u001b[0m \u001b[39mdef\u001b[39;00m \u001b[39mconnect\u001b[39m(\u001b[39mself\u001b[39m, \u001b[39m*\u001b[39mcargs, \u001b[39m*\u001b[39m\u001b[39m*\u001b[39mcparams):\n\u001b[0;32m    597\u001b[0m     \u001b[39m# inherits the docstring from interfaces.Dialect.connect\u001b[39;00m\n\u001b[1;32m--> 598\u001b[0m     \u001b[39mreturn\u001b[39;00m \u001b[39mself\u001b[39m\u001b[39m.\u001b[39mdbapi\u001b[39m.\u001b[39mconnect(\u001b[39m*\u001b[39mcargs, \u001b[39m*\u001b[39m\u001b[39m*\u001b[39mcparams)\n",
      "File \u001b[1;32m~\\AppData\\Local\\Packages\\PythonSoftwareFoundation.Python.3.10_qbz5n2kfra8p0\\LocalCache\\local-packages\\Python310\\site-packages\\psycopg2\\__init__.py:122\u001b[0m, in \u001b[0;36mconnect\u001b[1;34m(dsn, connection_factory, cursor_factory, **kwargs)\u001b[0m\n\u001b[0;32m    121\u001b[0m dsn \u001b[39m=\u001b[39m _ext\u001b[39m.\u001b[39mmake_dsn(dsn, \u001b[39m*\u001b[39m\u001b[39m*\u001b[39mkwargs)\n\u001b[1;32m--> 122\u001b[0m conn \u001b[39m=\u001b[39m _connect(dsn, connection_factory\u001b[39m=\u001b[39mconnection_factory, \u001b[39m*\u001b[39m\u001b[39m*\u001b[39mkwasync)\n\u001b[0;32m    123\u001b[0m \u001b[39mif\u001b[39;00m cursor_factory \u001b[39mis\u001b[39;00m \u001b[39mnot\u001b[39;00m \u001b[39mNone\u001b[39;00m:\n",
      "\u001b[1;31mOperationalError\u001b[0m: connection to server at \"localhost\" (::1), port 5432 failed: FATAL:  password authentication failed for user \"root\"\n",
      "\nThe above exception was the direct cause of the following exception:\n",
      "\u001b[1;31mOperationalError\u001b[0m                          Traceback (most recent call last)",
      "Cell \u001b[1;32mIn[9], line 1\u001b[0m\n\u001b[1;32m----> 1\u001b[0m engine\u001b[39m.\u001b[39;49mconnect()\n",
      "File \u001b[1;32m~\\AppData\\Local\\Packages\\PythonSoftwareFoundation.Python.3.10_qbz5n2kfra8p0\\LocalCache\\local-packages\\Python310\\site-packages\\sqlalchemy\\engine\\base.py:3315\u001b[0m, in \u001b[0;36mEngine.connect\u001b[1;34m(self, close_with_result)\u001b[0m\n\u001b[0;32m   3300\u001b[0m \u001b[39mdef\u001b[39;00m \u001b[39mconnect\u001b[39m(\u001b[39mself\u001b[39m, close_with_result\u001b[39m=\u001b[39m\u001b[39mFalse\u001b[39;00m):\n\u001b[0;32m   3301\u001b[0m     \u001b[39m\"\"\"Return a new :class:`_engine.Connection` object.\u001b[39;00m\n\u001b[0;32m   3302\u001b[0m \n\u001b[0;32m   3303\u001b[0m \u001b[39m    The :class:`_engine.Connection` object is a facade that uses a DBAPI\u001b[39;00m\n\u001b[1;32m   (...)\u001b[0m\n\u001b[0;32m   3312\u001b[0m \n\u001b[0;32m   3313\u001b[0m \u001b[39m    \"\"\"\u001b[39;00m\n\u001b[1;32m-> 3315\u001b[0m     \u001b[39mreturn\u001b[39;00m \u001b[39mself\u001b[39;49m\u001b[39m.\u001b[39;49m_connection_cls(\u001b[39mself\u001b[39;49m, close_with_result\u001b[39m=\u001b[39;49mclose_with_result)\n",
      "File \u001b[1;32m~\\AppData\\Local\\Packages\\PythonSoftwareFoundation.Python.3.10_qbz5n2kfra8p0\\LocalCache\\local-packages\\Python310\\site-packages\\sqlalchemy\\engine\\base.py:96\u001b[0m, in \u001b[0;36mConnection.__init__\u001b[1;34m(self, engine, connection, close_with_result, _branch_from, _execution_options, _dispatch, _has_events, _allow_revalidate)\u001b[0m\n\u001b[0;32m     91\u001b[0m     \u001b[39mself\u001b[39m\u001b[39m.\u001b[39m_has_events \u001b[39m=\u001b[39m _branch_from\u001b[39m.\u001b[39m_has_events\n\u001b[0;32m     92\u001b[0m \u001b[39melse\u001b[39;00m:\n\u001b[0;32m     93\u001b[0m     \u001b[39mself\u001b[39m\u001b[39m.\u001b[39m_dbapi_connection \u001b[39m=\u001b[39m (\n\u001b[0;32m     94\u001b[0m         connection\n\u001b[0;32m     95\u001b[0m         \u001b[39mif\u001b[39;00m connection \u001b[39mis\u001b[39;00m \u001b[39mnot\u001b[39;00m \u001b[39mNone\u001b[39;00m\n\u001b[1;32m---> 96\u001b[0m         \u001b[39melse\u001b[39;00m engine\u001b[39m.\u001b[39;49mraw_connection()\n\u001b[0;32m     97\u001b[0m     )\n\u001b[0;32m     99\u001b[0m     \u001b[39mself\u001b[39m\u001b[39m.\u001b[39m_transaction \u001b[39m=\u001b[39m \u001b[39mself\u001b[39m\u001b[39m.\u001b[39m_nested_transaction \u001b[39m=\u001b[39m \u001b[39mNone\u001b[39;00m\n\u001b[0;32m    100\u001b[0m     \u001b[39mself\u001b[39m\u001b[39m.\u001b[39m__savepoint_seq \u001b[39m=\u001b[39m \u001b[39m0\u001b[39m\n",
      "File \u001b[1;32m~\\AppData\\Local\\Packages\\PythonSoftwareFoundation.Python.3.10_qbz5n2kfra8p0\\LocalCache\\local-packages\\Python310\\site-packages\\sqlalchemy\\engine\\base.py:3394\u001b[0m, in \u001b[0;36mEngine.raw_connection\u001b[1;34m(self, _connection)\u001b[0m\n\u001b[0;32m   3372\u001b[0m \u001b[39mdef\u001b[39;00m \u001b[39mraw_connection\u001b[39m(\u001b[39mself\u001b[39m, _connection\u001b[39m=\u001b[39m\u001b[39mNone\u001b[39;00m):\n\u001b[0;32m   3373\u001b[0m     \u001b[39m\"\"\"Return a \"raw\" DBAPI connection from the connection pool.\u001b[39;00m\n\u001b[0;32m   3374\u001b[0m \n\u001b[0;32m   3375\u001b[0m \u001b[39m    The returned object is a proxied version of the DBAPI\u001b[39;00m\n\u001b[1;32m   (...)\u001b[0m\n\u001b[0;32m   3392\u001b[0m \n\u001b[0;32m   3393\u001b[0m \u001b[39m    \"\"\"\u001b[39;00m\n\u001b[1;32m-> 3394\u001b[0m     \u001b[39mreturn\u001b[39;00m \u001b[39mself\u001b[39;49m\u001b[39m.\u001b[39;49m_wrap_pool_connect(\u001b[39mself\u001b[39;49m\u001b[39m.\u001b[39;49mpool\u001b[39m.\u001b[39;49mconnect, _connection)\n",
      "File \u001b[1;32m~\\AppData\\Local\\Packages\\PythonSoftwareFoundation.Python.3.10_qbz5n2kfra8p0\\LocalCache\\local-packages\\Python310\\site-packages\\sqlalchemy\\engine\\base.py:3364\u001b[0m, in \u001b[0;36mEngine._wrap_pool_connect\u001b[1;34m(self, fn, connection)\u001b[0m\n\u001b[0;32m   3362\u001b[0m \u001b[39mexcept\u001b[39;00m dialect\u001b[39m.\u001b[39mdbapi\u001b[39m.\u001b[39mError \u001b[39mas\u001b[39;00m e:\n\u001b[0;32m   3363\u001b[0m     \u001b[39mif\u001b[39;00m connection \u001b[39mis\u001b[39;00m \u001b[39mNone\u001b[39;00m:\n\u001b[1;32m-> 3364\u001b[0m         Connection\u001b[39m.\u001b[39;49m_handle_dbapi_exception_noconnection(\n\u001b[0;32m   3365\u001b[0m             e, dialect, \u001b[39mself\u001b[39;49m\n\u001b[0;32m   3366\u001b[0m         )\n\u001b[0;32m   3367\u001b[0m     \u001b[39melse\u001b[39;00m:\n\u001b[0;32m   3368\u001b[0m         util\u001b[39m.\u001b[39mraise_(\n\u001b[0;32m   3369\u001b[0m             sys\u001b[39m.\u001b[39mexc_info()[\u001b[39m1\u001b[39m], with_traceback\u001b[39m=\u001b[39msys\u001b[39m.\u001b[39mexc_info()[\u001b[39m2\u001b[39m]\n\u001b[0;32m   3370\u001b[0m         )\n",
      "File \u001b[1;32m~\\AppData\\Local\\Packages\\PythonSoftwareFoundation.Python.3.10_qbz5n2kfra8p0\\LocalCache\\local-packages\\Python310\\site-packages\\sqlalchemy\\engine\\base.py:2198\u001b[0m, in \u001b[0;36mConnection._handle_dbapi_exception_noconnection\u001b[1;34m(cls, e, dialect, engine)\u001b[0m\n\u001b[0;32m   2196\u001b[0m     util\u001b[39m.\u001b[39mraise_(newraise, with_traceback\u001b[39m=\u001b[39mexc_info[\u001b[39m2\u001b[39m], from_\u001b[39m=\u001b[39me)\n\u001b[0;32m   2197\u001b[0m \u001b[39melif\u001b[39;00m should_wrap:\n\u001b[1;32m-> 2198\u001b[0m     util\u001b[39m.\u001b[39;49mraise_(\n\u001b[0;32m   2199\u001b[0m         sqlalchemy_exception, with_traceback\u001b[39m=\u001b[39;49mexc_info[\u001b[39m2\u001b[39;49m], from_\u001b[39m=\u001b[39;49me\n\u001b[0;32m   2200\u001b[0m     )\n\u001b[0;32m   2201\u001b[0m \u001b[39melse\u001b[39;00m:\n\u001b[0;32m   2202\u001b[0m     util\u001b[39m.\u001b[39mraise_(exc_info[\u001b[39m1\u001b[39m], with_traceback\u001b[39m=\u001b[39mexc_info[\u001b[39m2\u001b[39m])\n",
      "File \u001b[1;32m~\\AppData\\Local\\Packages\\PythonSoftwareFoundation.Python.3.10_qbz5n2kfra8p0\\LocalCache\\local-packages\\Python310\\site-packages\\sqlalchemy\\util\\compat.py:210\u001b[0m, in \u001b[0;36mraise_\u001b[1;34m(***failed resolving arguments***)\u001b[0m\n\u001b[0;32m    207\u001b[0m     exception\u001b[39m.\u001b[39m__cause__ \u001b[39m=\u001b[39m replace_context\n\u001b[0;32m    209\u001b[0m \u001b[39mtry\u001b[39;00m:\n\u001b[1;32m--> 210\u001b[0m     \u001b[39mraise\u001b[39;00m exception\n\u001b[0;32m    211\u001b[0m \u001b[39mfinally\u001b[39;00m:\n\u001b[0;32m    212\u001b[0m     \u001b[39m# credit to\u001b[39;00m\n\u001b[0;32m    213\u001b[0m     \u001b[39m# https://cosmicpercolator.com/2016/01/13/exception-leaks-in-python-2-and-3/\u001b[39;00m\n\u001b[0;32m    214\u001b[0m     \u001b[39m# as the __traceback__ object creates a cycle\u001b[39;00m\n\u001b[0;32m    215\u001b[0m     \u001b[39mdel\u001b[39;00m exception, replace_context, from_, with_traceback\n",
      "File \u001b[1;32m~\\AppData\\Local\\Packages\\PythonSoftwareFoundation.Python.3.10_qbz5n2kfra8p0\\LocalCache\\local-packages\\Python310\\site-packages\\sqlalchemy\\engine\\base.py:3361\u001b[0m, in \u001b[0;36mEngine._wrap_pool_connect\u001b[1;34m(self, fn, connection)\u001b[0m\n\u001b[0;32m   3359\u001b[0m dialect \u001b[39m=\u001b[39m \u001b[39mself\u001b[39m\u001b[39m.\u001b[39mdialect\n\u001b[0;32m   3360\u001b[0m \u001b[39mtry\u001b[39;00m:\n\u001b[1;32m-> 3361\u001b[0m     \u001b[39mreturn\u001b[39;00m fn()\n\u001b[0;32m   3362\u001b[0m \u001b[39mexcept\u001b[39;00m dialect\u001b[39m.\u001b[39mdbapi\u001b[39m.\u001b[39mError \u001b[39mas\u001b[39;00m e:\n\u001b[0;32m   3363\u001b[0m     \u001b[39mif\u001b[39;00m connection \u001b[39mis\u001b[39;00m \u001b[39mNone\u001b[39;00m:\n",
      "File \u001b[1;32m~\\AppData\\Local\\Packages\\PythonSoftwareFoundation.Python.3.10_qbz5n2kfra8p0\\LocalCache\\local-packages\\Python310\\site-packages\\sqlalchemy\\pool\\base.py:325\u001b[0m, in \u001b[0;36mPool.connect\u001b[1;34m(self)\u001b[0m\n\u001b[0;32m    317\u001b[0m \u001b[39mdef\u001b[39;00m \u001b[39mconnect\u001b[39m(\u001b[39mself\u001b[39m):\n\u001b[0;32m    318\u001b[0m     \u001b[39m\"\"\"Return a DBAPI connection from the pool.\u001b[39;00m\n\u001b[0;32m    319\u001b[0m \n\u001b[0;32m    320\u001b[0m \u001b[39m    The connection is instrumented such that when its\u001b[39;00m\n\u001b[1;32m   (...)\u001b[0m\n\u001b[0;32m    323\u001b[0m \n\u001b[0;32m    324\u001b[0m \u001b[39m    \"\"\"\u001b[39;00m\n\u001b[1;32m--> 325\u001b[0m     \u001b[39mreturn\u001b[39;00m _ConnectionFairy\u001b[39m.\u001b[39;49m_checkout(\u001b[39mself\u001b[39;49m)\n",
      "File \u001b[1;32m~\\AppData\\Local\\Packages\\PythonSoftwareFoundation.Python.3.10_qbz5n2kfra8p0\\LocalCache\\local-packages\\Python310\\site-packages\\sqlalchemy\\pool\\base.py:888\u001b[0m, in \u001b[0;36m_ConnectionFairy._checkout\u001b[1;34m(cls, pool, threadconns, fairy)\u001b[0m\n\u001b[0;32m    885\u001b[0m \u001b[39m@classmethod\u001b[39m\n\u001b[0;32m    886\u001b[0m \u001b[39mdef\u001b[39;00m \u001b[39m_checkout\u001b[39m(\u001b[39mcls\u001b[39m, pool, threadconns\u001b[39m=\u001b[39m\u001b[39mNone\u001b[39;00m, fairy\u001b[39m=\u001b[39m\u001b[39mNone\u001b[39;00m):\n\u001b[0;32m    887\u001b[0m     \u001b[39mif\u001b[39;00m \u001b[39mnot\u001b[39;00m fairy:\n\u001b[1;32m--> 888\u001b[0m         fairy \u001b[39m=\u001b[39m _ConnectionRecord\u001b[39m.\u001b[39;49mcheckout(pool)\n\u001b[0;32m    890\u001b[0m         fairy\u001b[39m.\u001b[39m_pool \u001b[39m=\u001b[39m pool\n\u001b[0;32m    891\u001b[0m         fairy\u001b[39m.\u001b[39m_counter \u001b[39m=\u001b[39m \u001b[39m0\u001b[39m\n",
      "File \u001b[1;32m~\\AppData\\Local\\Packages\\PythonSoftwareFoundation.Python.3.10_qbz5n2kfra8p0\\LocalCache\\local-packages\\Python310\\site-packages\\sqlalchemy\\pool\\base.py:491\u001b[0m, in \u001b[0;36m_ConnectionRecord.checkout\u001b[1;34m(cls, pool)\u001b[0m\n\u001b[0;32m    489\u001b[0m \u001b[39m@classmethod\u001b[39m\n\u001b[0;32m    490\u001b[0m \u001b[39mdef\u001b[39;00m \u001b[39mcheckout\u001b[39m(\u001b[39mcls\u001b[39m, pool):\n\u001b[1;32m--> 491\u001b[0m     rec \u001b[39m=\u001b[39m pool\u001b[39m.\u001b[39;49m_do_get()\n\u001b[0;32m    492\u001b[0m     \u001b[39mtry\u001b[39;00m:\n\u001b[0;32m    493\u001b[0m         dbapi_connection \u001b[39m=\u001b[39m rec\u001b[39m.\u001b[39mget_connection()\n",
      "File \u001b[1;32m~\\AppData\\Local\\Packages\\PythonSoftwareFoundation.Python.3.10_qbz5n2kfra8p0\\LocalCache\\local-packages\\Python310\\site-packages\\sqlalchemy\\pool\\impl.py:145\u001b[0m, in \u001b[0;36mQueuePool._do_get\u001b[1;34m(self)\u001b[0m\n\u001b[0;32m    143\u001b[0m         \u001b[39mreturn\u001b[39;00m \u001b[39mself\u001b[39m\u001b[39m.\u001b[39m_create_connection()\n\u001b[0;32m    144\u001b[0m     \u001b[39mexcept\u001b[39;00m:\n\u001b[1;32m--> 145\u001b[0m         \u001b[39mwith\u001b[39;00m util\u001b[39m.\u001b[39msafe_reraise():\n\u001b[0;32m    146\u001b[0m             \u001b[39mself\u001b[39m\u001b[39m.\u001b[39m_dec_overflow()\n\u001b[0;32m    147\u001b[0m \u001b[39melse\u001b[39;00m:\n",
      "File \u001b[1;32m~\\AppData\\Local\\Packages\\PythonSoftwareFoundation.Python.3.10_qbz5n2kfra8p0\\LocalCache\\local-packages\\Python310\\site-packages\\sqlalchemy\\util\\langhelpers.py:70\u001b[0m, in \u001b[0;36msafe_reraise.__exit__\u001b[1;34m(self, type_, value, traceback)\u001b[0m\n\u001b[0;32m     68\u001b[0m     \u001b[39mself\u001b[39m\u001b[39m.\u001b[39m_exc_info \u001b[39m=\u001b[39m \u001b[39mNone\u001b[39;00m  \u001b[39m# remove potential circular references\u001b[39;00m\n\u001b[0;32m     69\u001b[0m     \u001b[39mif\u001b[39;00m \u001b[39mnot\u001b[39;00m \u001b[39mself\u001b[39m\u001b[39m.\u001b[39mwarn_only:\n\u001b[1;32m---> 70\u001b[0m         compat\u001b[39m.\u001b[39;49mraise_(\n\u001b[0;32m     71\u001b[0m             exc_value,\n\u001b[0;32m     72\u001b[0m             with_traceback\u001b[39m=\u001b[39;49mexc_tb,\n\u001b[0;32m     73\u001b[0m         )\n\u001b[0;32m     74\u001b[0m \u001b[39melse\u001b[39;00m:\n\u001b[0;32m     75\u001b[0m     \u001b[39mif\u001b[39;00m \u001b[39mnot\u001b[39;00m compat\u001b[39m.\u001b[39mpy3k \u001b[39mand\u001b[39;00m \u001b[39mself\u001b[39m\u001b[39m.\u001b[39m_exc_info \u001b[39mand\u001b[39;00m \u001b[39mself\u001b[39m\u001b[39m.\u001b[39m_exc_info[\u001b[39m1\u001b[39m]:\n\u001b[0;32m     76\u001b[0m         \u001b[39m# emulate Py3K's behavior of telling us when an exception\u001b[39;00m\n\u001b[0;32m     77\u001b[0m         \u001b[39m# occurs in an exception handler.\u001b[39;00m\n",
      "File \u001b[1;32m~\\AppData\\Local\\Packages\\PythonSoftwareFoundation.Python.3.10_qbz5n2kfra8p0\\LocalCache\\local-packages\\Python310\\site-packages\\sqlalchemy\\util\\compat.py:210\u001b[0m, in \u001b[0;36mraise_\u001b[1;34m(***failed resolving arguments***)\u001b[0m\n\u001b[0;32m    207\u001b[0m     exception\u001b[39m.\u001b[39m__cause__ \u001b[39m=\u001b[39m replace_context\n\u001b[0;32m    209\u001b[0m \u001b[39mtry\u001b[39;00m:\n\u001b[1;32m--> 210\u001b[0m     \u001b[39mraise\u001b[39;00m exception\n\u001b[0;32m    211\u001b[0m \u001b[39mfinally\u001b[39;00m:\n\u001b[0;32m    212\u001b[0m     \u001b[39m# credit to\u001b[39;00m\n\u001b[0;32m    213\u001b[0m     \u001b[39m# https://cosmicpercolator.com/2016/01/13/exception-leaks-in-python-2-and-3/\u001b[39;00m\n\u001b[0;32m    214\u001b[0m     \u001b[39m# as the __traceback__ object creates a cycle\u001b[39;00m\n\u001b[0;32m    215\u001b[0m     \u001b[39mdel\u001b[39;00m exception, replace_context, from_, with_traceback\n",
      "File \u001b[1;32m~\\AppData\\Local\\Packages\\PythonSoftwareFoundation.Python.3.10_qbz5n2kfra8p0\\LocalCache\\local-packages\\Python310\\site-packages\\sqlalchemy\\pool\\impl.py:143\u001b[0m, in \u001b[0;36mQueuePool._do_get\u001b[1;34m(self)\u001b[0m\n\u001b[0;32m    141\u001b[0m \u001b[39mif\u001b[39;00m \u001b[39mself\u001b[39m\u001b[39m.\u001b[39m_inc_overflow():\n\u001b[0;32m    142\u001b[0m     \u001b[39mtry\u001b[39;00m:\n\u001b[1;32m--> 143\u001b[0m         \u001b[39mreturn\u001b[39;00m \u001b[39mself\u001b[39;49m\u001b[39m.\u001b[39;49m_create_connection()\n\u001b[0;32m    144\u001b[0m     \u001b[39mexcept\u001b[39;00m:\n\u001b[0;32m    145\u001b[0m         \u001b[39mwith\u001b[39;00m util\u001b[39m.\u001b[39msafe_reraise():\n",
      "File \u001b[1;32m~\\AppData\\Local\\Packages\\PythonSoftwareFoundation.Python.3.10_qbz5n2kfra8p0\\LocalCache\\local-packages\\Python310\\site-packages\\sqlalchemy\\pool\\base.py:271\u001b[0m, in \u001b[0;36mPool._create_connection\u001b[1;34m(self)\u001b[0m\n\u001b[0;32m    268\u001b[0m \u001b[39mdef\u001b[39;00m \u001b[39m_create_connection\u001b[39m(\u001b[39mself\u001b[39m):\n\u001b[0;32m    269\u001b[0m     \u001b[39m\"\"\"Called by subclasses to create a new ConnectionRecord.\"\"\"\u001b[39;00m\n\u001b[1;32m--> 271\u001b[0m     \u001b[39mreturn\u001b[39;00m _ConnectionRecord(\u001b[39mself\u001b[39;49m)\n",
      "File \u001b[1;32m~\\AppData\\Local\\Packages\\PythonSoftwareFoundation.Python.3.10_qbz5n2kfra8p0\\LocalCache\\local-packages\\Python310\\site-packages\\sqlalchemy\\pool\\base.py:386\u001b[0m, in \u001b[0;36m_ConnectionRecord.__init__\u001b[1;34m(self, pool, connect)\u001b[0m\n\u001b[0;32m    384\u001b[0m \u001b[39mself\u001b[39m\u001b[39m.\u001b[39m__pool \u001b[39m=\u001b[39m pool\n\u001b[0;32m    385\u001b[0m \u001b[39mif\u001b[39;00m connect:\n\u001b[1;32m--> 386\u001b[0m     \u001b[39mself\u001b[39;49m\u001b[39m.\u001b[39;49m__connect()\n\u001b[0;32m    387\u001b[0m \u001b[39mself\u001b[39m\u001b[39m.\u001b[39mfinalize_callback \u001b[39m=\u001b[39m deque()\n",
      "File \u001b[1;32m~\\AppData\\Local\\Packages\\PythonSoftwareFoundation.Python.3.10_qbz5n2kfra8p0\\LocalCache\\local-packages\\Python310\\site-packages\\sqlalchemy\\pool\\base.py:684\u001b[0m, in \u001b[0;36m_ConnectionRecord.__connect\u001b[1;34m(self)\u001b[0m\n\u001b[0;32m    682\u001b[0m     \u001b[39mself\u001b[39m\u001b[39m.\u001b[39mfresh \u001b[39m=\u001b[39m \u001b[39mTrue\u001b[39;00m\n\u001b[0;32m    683\u001b[0m \u001b[39mexcept\u001b[39;00m \u001b[39mException\u001b[39;00m \u001b[39mas\u001b[39;00m e:\n\u001b[1;32m--> 684\u001b[0m     \u001b[39mwith\u001b[39;00m util\u001b[39m.\u001b[39msafe_reraise():\n\u001b[0;32m    685\u001b[0m         pool\u001b[39m.\u001b[39mlogger\u001b[39m.\u001b[39mdebug(\u001b[39m\"\u001b[39m\u001b[39mError on connect(): \u001b[39m\u001b[39m%s\u001b[39;00m\u001b[39m\"\u001b[39m, e)\n\u001b[0;32m    686\u001b[0m \u001b[39melse\u001b[39;00m:\n\u001b[0;32m    687\u001b[0m     \u001b[39m# in SQLAlchemy 1.4 the first_connect event is not used by\u001b[39;00m\n\u001b[0;32m    688\u001b[0m     \u001b[39m# the engine, so this will usually not be set\u001b[39;00m\n",
      "File \u001b[1;32m~\\AppData\\Local\\Packages\\PythonSoftwareFoundation.Python.3.10_qbz5n2kfra8p0\\LocalCache\\local-packages\\Python310\\site-packages\\sqlalchemy\\util\\langhelpers.py:70\u001b[0m, in \u001b[0;36msafe_reraise.__exit__\u001b[1;34m(self, type_, value, traceback)\u001b[0m\n\u001b[0;32m     68\u001b[0m     \u001b[39mself\u001b[39m\u001b[39m.\u001b[39m_exc_info \u001b[39m=\u001b[39m \u001b[39mNone\u001b[39;00m  \u001b[39m# remove potential circular references\u001b[39;00m\n\u001b[0;32m     69\u001b[0m     \u001b[39mif\u001b[39;00m \u001b[39mnot\u001b[39;00m \u001b[39mself\u001b[39m\u001b[39m.\u001b[39mwarn_only:\n\u001b[1;32m---> 70\u001b[0m         compat\u001b[39m.\u001b[39;49mraise_(\n\u001b[0;32m     71\u001b[0m             exc_value,\n\u001b[0;32m     72\u001b[0m             with_traceback\u001b[39m=\u001b[39;49mexc_tb,\n\u001b[0;32m     73\u001b[0m         )\n\u001b[0;32m     74\u001b[0m \u001b[39melse\u001b[39;00m:\n\u001b[0;32m     75\u001b[0m     \u001b[39mif\u001b[39;00m \u001b[39mnot\u001b[39;00m compat\u001b[39m.\u001b[39mpy3k \u001b[39mand\u001b[39;00m \u001b[39mself\u001b[39m\u001b[39m.\u001b[39m_exc_info \u001b[39mand\u001b[39;00m \u001b[39mself\u001b[39m\u001b[39m.\u001b[39m_exc_info[\u001b[39m1\u001b[39m]:\n\u001b[0;32m     76\u001b[0m         \u001b[39m# emulate Py3K's behavior of telling us when an exception\u001b[39;00m\n\u001b[0;32m     77\u001b[0m         \u001b[39m# occurs in an exception handler.\u001b[39;00m\n",
      "File \u001b[1;32m~\\AppData\\Local\\Packages\\PythonSoftwareFoundation.Python.3.10_qbz5n2kfra8p0\\LocalCache\\local-packages\\Python310\\site-packages\\sqlalchemy\\util\\compat.py:210\u001b[0m, in \u001b[0;36mraise_\u001b[1;34m(***failed resolving arguments***)\u001b[0m\n\u001b[0;32m    207\u001b[0m     exception\u001b[39m.\u001b[39m__cause__ \u001b[39m=\u001b[39m replace_context\n\u001b[0;32m    209\u001b[0m \u001b[39mtry\u001b[39;00m:\n\u001b[1;32m--> 210\u001b[0m     \u001b[39mraise\u001b[39;00m exception\n\u001b[0;32m    211\u001b[0m \u001b[39mfinally\u001b[39;00m:\n\u001b[0;32m    212\u001b[0m     \u001b[39m# credit to\u001b[39;00m\n\u001b[0;32m    213\u001b[0m     \u001b[39m# https://cosmicpercolator.com/2016/01/13/exception-leaks-in-python-2-and-3/\u001b[39;00m\n\u001b[0;32m    214\u001b[0m     \u001b[39m# as the __traceback__ object creates a cycle\u001b[39;00m\n\u001b[0;32m    215\u001b[0m     \u001b[39mdel\u001b[39;00m exception, replace_context, from_, with_traceback\n",
      "File \u001b[1;32m~\\AppData\\Local\\Packages\\PythonSoftwareFoundation.Python.3.10_qbz5n2kfra8p0\\LocalCache\\local-packages\\Python310\\site-packages\\sqlalchemy\\pool\\base.py:680\u001b[0m, in \u001b[0;36m_ConnectionRecord.__connect\u001b[1;34m(self)\u001b[0m\n\u001b[0;32m    678\u001b[0m \u001b[39mtry\u001b[39;00m:\n\u001b[0;32m    679\u001b[0m     \u001b[39mself\u001b[39m\u001b[39m.\u001b[39mstarttime \u001b[39m=\u001b[39m time\u001b[39m.\u001b[39mtime()\n\u001b[1;32m--> 680\u001b[0m     \u001b[39mself\u001b[39m\u001b[39m.\u001b[39mdbapi_connection \u001b[39m=\u001b[39m connection \u001b[39m=\u001b[39m pool\u001b[39m.\u001b[39;49m_invoke_creator(\u001b[39mself\u001b[39;49m)\n\u001b[0;32m    681\u001b[0m     pool\u001b[39m.\u001b[39mlogger\u001b[39m.\u001b[39mdebug(\u001b[39m\"\u001b[39m\u001b[39mCreated new connection \u001b[39m\u001b[39m%r\u001b[39;00m\u001b[39m\"\u001b[39m, connection)\n\u001b[0;32m    682\u001b[0m     \u001b[39mself\u001b[39m\u001b[39m.\u001b[39mfresh \u001b[39m=\u001b[39m \u001b[39mTrue\u001b[39;00m\n",
      "File \u001b[1;32m~\\AppData\\Local\\Packages\\PythonSoftwareFoundation.Python.3.10_qbz5n2kfra8p0\\LocalCache\\local-packages\\Python310\\site-packages\\sqlalchemy\\engine\\create.py:578\u001b[0m, in \u001b[0;36mcreate_engine.<locals>.connect\u001b[1;34m(connection_record)\u001b[0m\n\u001b[0;32m    576\u001b[0m         \u001b[39mif\u001b[39;00m connection \u001b[39mis\u001b[39;00m \u001b[39mnot\u001b[39;00m \u001b[39mNone\u001b[39;00m:\n\u001b[0;32m    577\u001b[0m             \u001b[39mreturn\u001b[39;00m connection\n\u001b[1;32m--> 578\u001b[0m \u001b[39mreturn\u001b[39;00m dialect\u001b[39m.\u001b[39mconnect(\u001b[39m*\u001b[39mcargs, \u001b[39m*\u001b[39m\u001b[39m*\u001b[39mcparams)\n",
      "File \u001b[1;32m~\\AppData\\Local\\Packages\\PythonSoftwareFoundation.Python.3.10_qbz5n2kfra8p0\\LocalCache\\local-packages\\Python310\\site-packages\\sqlalchemy\\engine\\default.py:598\u001b[0m, in \u001b[0;36mDefaultDialect.connect\u001b[1;34m(self, *cargs, **cparams)\u001b[0m\n\u001b[0;32m    596\u001b[0m \u001b[39mdef\u001b[39;00m \u001b[39mconnect\u001b[39m(\u001b[39mself\u001b[39m, \u001b[39m*\u001b[39mcargs, \u001b[39m*\u001b[39m\u001b[39m*\u001b[39mcparams):\n\u001b[0;32m    597\u001b[0m     \u001b[39m# inherits the docstring from interfaces.Dialect.connect\u001b[39;00m\n\u001b[1;32m--> 598\u001b[0m     \u001b[39mreturn\u001b[39;00m \u001b[39mself\u001b[39m\u001b[39m.\u001b[39mdbapi\u001b[39m.\u001b[39mconnect(\u001b[39m*\u001b[39mcargs, \u001b[39m*\u001b[39m\u001b[39m*\u001b[39mcparams)\n",
      "File \u001b[1;32m~\\AppData\\Local\\Packages\\PythonSoftwareFoundation.Python.3.10_qbz5n2kfra8p0\\LocalCache\\local-packages\\Python310\\site-packages\\psycopg2\\__init__.py:122\u001b[0m, in \u001b[0;36mconnect\u001b[1;34m(dsn, connection_factory, cursor_factory, **kwargs)\u001b[0m\n\u001b[0;32m    119\u001b[0m     kwasync[\u001b[39m'\u001b[39m\u001b[39masync_\u001b[39m\u001b[39m'\u001b[39m] \u001b[39m=\u001b[39m kwargs\u001b[39m.\u001b[39mpop(\u001b[39m'\u001b[39m\u001b[39masync_\u001b[39m\u001b[39m'\u001b[39m)\n\u001b[0;32m    121\u001b[0m dsn \u001b[39m=\u001b[39m _ext\u001b[39m.\u001b[39mmake_dsn(dsn, \u001b[39m*\u001b[39m\u001b[39m*\u001b[39mkwargs)\n\u001b[1;32m--> 122\u001b[0m conn \u001b[39m=\u001b[39m _connect(dsn, connection_factory\u001b[39m=\u001b[39mconnection_factory, \u001b[39m*\u001b[39m\u001b[39m*\u001b[39mkwasync)\n\u001b[0;32m    123\u001b[0m \u001b[39mif\u001b[39;00m cursor_factory \u001b[39mis\u001b[39;00m \u001b[39mnot\u001b[39;00m \u001b[39mNone\u001b[39;00m:\n\u001b[0;32m    124\u001b[0m     conn\u001b[39m.\u001b[39mcursor_factory \u001b[39m=\u001b[39m cursor_factory\n",
      "\u001b[1;31mOperationalError\u001b[0m: (psycopg2.OperationalError) connection to server at \"localhost\" (::1), port 5432 failed: FATAL:  password authentication failed for user \"root\"\n\n(Background on this error at: https://sqlalche.me/e/14/e3q8)"
     ]
    }
   ],
   "source": [
    "engine.connect()"
   ]
  },
  {
   "cell_type": "code",
   "execution_count": null,
   "metadata": {},
   "outputs": [],
   "source": []
  }
 ],
 "metadata": {
  "kernelspec": {
   "display_name": "Python 3",
   "language": "python",
   "name": "python3"
  },
  "language_info": {
   "codemirror_mode": {
    "name": "ipython",
    "version": 3
   },
   "file_extension": ".py",
   "mimetype": "text/x-python",
   "name": "python",
   "nbconvert_exporter": "python",
   "pygments_lexer": "ipython3",
   "version": "3.10.9 (tags/v3.10.9:1dd9be6, Dec  6 2022, 20:01:21) [MSC v.1934 64 bit (AMD64)]"
  },
  "orig_nbformat": 4,
  "vscode": {
   "interpreter": {
    "hash": "a6ec73095c00c4a0148934a80420ace368c5da9b028d5b3dce6ff5fa5f542558"
   }
  }
 },
 "nbformat": 4,
 "nbformat_minor": 2
}
